<?xml version="1.0" encoding="UTF-8"?>
<!-- Generated by org.testng.reporters.JUnitReportReporter -->
<testsuite hostname="aniket-Latitude-3410" failures="1" tests="2" name="exportPackage.ExportSitevisitsTest" time="36.144" errors="0" timestamp="2023-07-11T18:31:16 IST" skipped="1">
  <testcase classname="exportPackage.ExportSitevisitsTest" name="exportSitevisitsTest" time="16.510">
    <skipped/>
  </testcase> <!-- exportSitevisitsTest -->
  <system-out/>
  <testcase classname="exportPackage.ExportSitevisitsTest" name="exportSitevisitsTest" time="19.634">
    <failure message="expected [Export has been scheduled and will be emailed to tanvi@amuratech.com.] but found [{&quot;message&quot;:&quot;You already have 20 Export/Reassign leads scheduled. Please wait for it to finish and then try again.&quot;}]" type="java.lang.AssertionError">
      <![CDATA[java.lang.AssertionError: expected [Export has been scheduled and will be emailed to tanvi@amuratech.com.] but found [{"message":"You already have 20 Export/Reassign leads scheduled. Please wait for it to finish and then try again."}]
at org.testng.Assert.fail(Assert.java:110)
at org.testng.Assert.failNotEquals(Assert.java:1577)
at org.testng.Assert.assertEqualsImpl(Assert.java:149)
at org.testng.Assert.assertEquals(Assert.java:131)
at org.testng.Assert.assertEquals(Assert.java:655)
at org.testng.Assert.assertEquals(Assert.java:665)
at exportPackage.ExportSitevisitsTest.exportSitevisitsTest(ExportSitevisitsTest.java:45)
at java.base/jdk.internal.reflect.NativeMethodAccessorImpl.invoke0(Native Method)
at java.base/jdk.internal.reflect.NativeMethodAccessorImpl.invoke(NativeMethodAccessorImpl.java:77)
at java.base/jdk.internal.reflect.DelegatingMethodAccessorImpl.invoke(DelegatingMethodAccessorImpl.java:43)
at java.base/java.lang.reflect.Method.invoke(Method.java:568)
at org.testng.internal.invokers.MethodInvocationHelper.invokeMethod(MethodInvocationHelper.java:139)
at org.testng.internal.invokers.TestInvoker.invokeMethod(TestInvoker.java:677)
at org.testng.internal.invokers.TestInvoker.retryFailed(TestInvoker.java:263)
at org.testng.internal.invokers.MethodRunner.runInSequence(MethodRunner.java:62)
at org.testng.internal.invokers.TestInvoker$MethodInvocationAgent.invoke(TestInvoker.java:969)
at org.testng.internal.invokers.TestInvoker.invokeTestMethods(TestInvoker.java:194)
at org.testng.internal.invokers.TestMethodWorker.invokeTestMethods(TestMethodWorker.java:148)
at org.testng.internal.invokers.TestMethodWorker.run(TestMethodWorker.java:128)
at java.base/java.util.concurrent.ThreadPoolExecutor.runWorker(ThreadPoolExecutor.java:1136)
at java.base/java.util.concurrent.ThreadPoolExecutor$Worker.run(ThreadPoolExecutor.java:635)
at java.base/java.lang.Thread.run(Thread.java:833)
]]>
    </failure>
  </testcase> <!-- exportSitevisitsTest -->
  <system-out/>
</testsuite> <!-- exportPackage.ExportSitevisitsTest -->
